Workbook

Sheet GPT-4o
A1: 欲求推論 | B1: 適合率 | C1: 再現率 | D1: F値平均 | G1: 物推論 | H1: 適合率 | I1: 再現率 | J1: F値平均 | K1: 平均トークン数
A2: 閾値：0.10 | B2: =test_rag_border01_4o!N5 -> 0.095 | C2: =test_rag_border01_4o!O5 -> 0.977 | D2: =test_rag_border01_4o!P5 -> 0.171 | G2: 閾値：0.10 | H2: =test_rag_border01_4o!N2 -> 0.44 | I2: =test_rag_border01_4o!O2 -> 0.756 | J2: =test_rag_border01_4o!P2 -> 0.49680645 | K2: =test_rag_border01_4o!O7 -> 395.23656
A3: 閾値：0.20 | B3: =test_rag_border02_4o!N5 -> 0.207 | C3: =test_rag_border02_4o!O5 -> 0.839 | D3: =test_rag_border02_4o!P5 -> 0.291 | G3: 閾値：0.20 | H3: =test_rag_border02_4o!N2 -> 0.539 | I3: =test_rag_border02_4o!O2 -> 0.631 | J3: =test_rag_border02_4o!P2 -> 0.54031183 | K3: =test_rag_border02_4o!O7 -> 281.58065
A4: 閾値：0.30 | B4: =test_rag_border03_4o!N5 -> 0.309 | C4: =test_rag_border03_4o!O5 -> 0.369 | D4: =test_rag_border03_4o!P5 -> 0.308 | G4: 閾値：0.30 | H4: =test_rag_border03_4o!N2 -> 0.395 | I4: =test_rag_border03_4o!O2 -> 0.496 | J4: =test_rag_border03_4o!P2 -> 0.40022581 | K4: =test_rag_border03_4o!O7 -> 155.86022

Sheet GPT-4o-mini
A1: 欲求推論 | B1: 適合率 | C1: 再現率 | D1: F値平均 | G1: 物推論 | H1: 適合率 | I1: 再現率 | J1: F値平均 | K1: 平均トークン数
A2: 閾値：0.10 | B2: =test_rag_border01!N5 -> 0.095 | C2: =test_rag_border01!O5 -> 0.977 | D2: =test_rag_border01!P5 -> 0.171 | G2: 閾値：0.10 | H2: =test_rag_border01!N2 -> 0.549 | I2: =test_rag_border01!O2 -> 0.593 | J2: =test_rag_border01!P2 -> 0.527 | K2: =test_rag_border01!O7 -> 384.10753
A3: 閾値：0.20 | B3: =test_rag_border02!N5 -> 0.205 | C3: =test_rag_border02!O5 -> 0.839 | D3: =test_rag_border02!P5 -> 0.29 | G3: 閾値：0.20 | H3: =test_rag_border02!N2 -> 0.583 | I3: =test_rag_border02!O2 -> 0.627 | J3: =test_rag_border02!P2 -> 0.55205376 | K3: =test_rag_border02!O7 -> 281.03226
A4: 閾値：0.30 | B4: =test_rag_border03!N5 -> 0.308 | C4: =test_rag_border03!O5 -> 0.369 | D4: =test_rag_border03!P5 -> 0.307 | G4: 閾値：0.30 | H4: =test_rag_border03!N2 -> 0.454 | I4: =test_rag_border03!O2 -> 0.459 | J4: =test_rag_border03!P2 -> 0.42206452 | K4: =test_rag_border03!O7 -> 149.82796

Sheet test_rag_border01_4o
A1: 発話事例 | B1: 欲求の種類 | C1: 正解の物 | D1: rag出力 | E1: 物の出力 | F1: 部屋 | G1: 適合率(欲求) | H1: 再現率(欲求) | I1: F値(欲求) | J1: 適合率(物) | K1: 再現率(物) | L1: トークン数 | M1: F値（物） | N1: 適合率 | O1: 再現率 | P1: F値平均
A2: Is there something to wipe my nose? If so where is it? | B2: Emission,Order | C2: tissue,table,toilet paper | D2: Emission,Breathing,Conservance,Sensory,Toxicity avoidance,Nursing,Exhibition,Thirst,Nurturance,Order,Exposition,Injury avoidance,Sleep,Temperature,Retention,Construction,Sexual,Achievement,Laziness,Cognizance | E2: towel,toilet paper,tissue | F2: bathroom,living room | G2: 0.1 | H2: 1 | I2: =IF(G2+H2=0,0,2*G2*H2/(G2+H2)) -> 0.18181818 | J2: 0.667 | K2: 0.667 | L2: 343 | M2: =IF(J2+K2=0,0,ROUND(2*J2*K2/(J2+K2),3)) -> 0.667 | N2: =ROUND(AVERAGE(J2:J94),3) -> 0.44 | O2: =ROUND(AVERAGE(K2:K94),3) -> 0.756 | P2: =SUM(M2:M94)/93 -> 0.49680645
A3: Where can I take a nap? | B3: Laziness,Sleep | C3: bed,chair,sofa,private room,floor | D3: Sleep,Laziness,Play,Nursing,Thirst,Nurturance,Sensory,Hunger,Injury avoidance,Temperature,Achievement,Breathing,Conservance,Emission,Exhibition,Cognizance,Sexual,Order,Exposition,Retention | E3: bed,sofa,private room,closet,chair,rug,pillow | F3: kitchen,living room,bathroom,bedroom | G3: 0.1 | H3: 1 | I3: =IF(G3+H3=0,0,2*G3*H3/(G3+H3)) -> 0.18181818 | J3: 0.571 | K3: 0.8 | L3: 404 | M3: =IF(J3+K3=0,0,ROUND(2*J3*K3/(J3+K3),3)) -> 0.666
A4: Where can I wash my hands? | B4: Toxicity avoidance | C4: sink,faucet,toilet | D4: Conservance,Emission,Toxicity avoidance,Nursing,Nurturance,Sensory,Exhibition,Thirst,Exposition,Temperature,Breathing,Retention,Injury avoidance,Order,Play,Sexual,Construction,Sleep,Hunger,Cognizance | E4: sink,toilet,bowl of dishes,faucet,bathtub,washing machine,bathroom counter | F4: bathroom,kitchen | G4: 0.05 | H4: 1 | I4: =IF(G4+H4=0,0,2*G4*H4/(G4+H4)) -> 0.095238095 | J4: 0.429 | K4: 1 | L4: 405 | M4: =IF(J4+K4=0,0,ROUND(2*J4*K4/(J4+K4),3)) -> 0.6
A5: Where should I store fruits that I want to last long? | B5: Conservance,Order | C5: refrigerator,kitchen cabinet | D5: Hunger,Retention,Conservance,Order,Construction,Thirst,Nursing,Exhibition,Nurturance,Sleep,Acquisition,Sensory,Injury avoidance,Play,Sexual,Temperature,Laziness,Toxicity avoidance,Achievement,Exposition | E5: refrigerator,kitchen cabinet,closet,closet drawers,bathroom cabinet,box | F5: bedroom,bathroom,living room,kitchen | G5: 0.1 | H5: 1 | I5: =IF(G5+H5=0,0,2*G5*H5/(G5+H5)) -> 0.18181818 | J5: 0.333 | K5: 1 | L5: 410 | M5: =IF(J5+K5=0,0,ROUND(2*J5*K5/(J5+K5),3)) -> 0.5 | N5: =ROUND(AVERAGE(G2:G94),3) -> 0.095 | O5: =ROUND(AVERAGE(H2:H94),3) -> 0.977 | P5: =ROUND(AVERAGE(I2:I94),3) -> 0.171
A6: Where can I take notes? | B6: Cognizance,Exposition | C6: desk,table,computer,mobile phone | D6: Cognizance,Exposition,Sensory,Acquisition,Achievement,Order,Construction,Retention,Exhibition,Conservance,Play,Injury avoidance,Breathing,Nurturance,Sleep,Toxicity avoidance,Laziness,Emission,Nursing,Sexual | E6: keyboard,book,mobile phone,tablet,computer,desk,table,notebook,bookshelf,closet,folder,closet drawers,books | F6: kitchen,bedroom,bathroom,living room | G6: 0.1 | H6: 1 | I6: =IF(G6+H6=0,0,2*G6*H6/(G6+H6)) -> 0.18181818 | J6: 0.308 | K6: 1 | L6: 351 | M6: =IF(J6+K6=0,0,ROUND(2*J6*K6/(J6+K6),3)) -> 0.471 | O6: 平均トークン
A7: Where can I brush my teeth? | B7: Conservance,Toxicity avoidance | C7: toothbrush,toothpaste,faucet,sink,toilet | D7: Toxicity avoidance,Conservance,Nursing,Nurturance,Emission,Sleep,Retention,Exhibition,Breathing,Sensory,Injury avoidance,Thirst,Exposition,Order,Hunger,Sexual,Achievement,Construction,Play,Acquisition | E7: sink,faucet,toothbrush,toothpaste,bathroom counter,bathroom cabinet | F7: bathroom,kitchen | G7: 0.1 | H7: 1 | I7: =IF(G7+H7=0,0,2*G7*H7/(G7+H7)) -> 0.18181818 | J7: 0.667 | K7: 0.8 | L7: 403 | M7: =IF(J7+K7=0,0,ROUND(2*J7*K7/(J7+K7),3)) -> 0.727 | O7: =AVERAGE(L2:L94) -> 395.23656
A8: Where can I set if I want to warmup? | B8: Temperature | C8: stove,bed | D8: Temperature,Play,Laziness,Injury avoidance,Thirst,Sleep,Hunger,Achievement,Conservance,Exhibition,Nursing,Order,Sensory,Emission,Exposition,Breathing,Acquisition,Nurturance,Cognizance,Toxicity avoidance | E8: microwave,stove,oven tray,refrigerator,coffee maker,cooking pot,coffee pot,ceiling lamp,table lamp,electric fan | F8: bedroom,bathroom,living room,kitchen | G8: 0.05 | H8: 1 | I8: =IF(G8+H8=0,0,2*G8*H8/(G8+H8)) -> 0.095238095 | J8: 0.1 | K8: 0.5 | L8: 417 | M8: =IF(J8+K8=0,0,ROUND(2*J8*K8/(J8+K8),3)) -> 0.167 | O8: 標準偏差
A9: Where can I check my appearance? | B9: Order,Exhibition,Exposition | C9: mirror | D9: Exhibition,Construction,Order,Sexual,Sensory,Exposition,Cognizance,Breathing,Conservance,Injury avoidance,Achievement,Emission,Temperature,Sleep,Hunger,Acquisition,Retention,Thirst,Nurturance,Nursing | E9: mirror | F9: bathroom | G9: 0.15 | H9: 1 | I9: =IF(G9+H9=0,0,2*G9*H9/(G9+H9)) -> 0.26086957 | J9: 1 | K9: 1 | L9: 381 | M9: =IF(J9+K9=0,0,ROUND(2*J9*K9/(J9+K9),3)) -> 1 | O9: =_xlfn.STDEV.P(L2:L94) -> 27.37411
A10: Where should I put my jackets? | B10: Order,Conservance | C10: closet,hanger | D10: Exhibition,Temperature,Order,Retention,Sexual,Exposition,Injury avoidance,Nursing,Sleep,Hunger,Conservance,Construction,Acquisition,Emission,Thirst,Sensory,Laziness,Play,Nurturance,Achievement | E10: closet,wardrobe,closet drawers,coat rack,hanger | F10: living room,bathroom,bedroom | G10: 0.1 | H10: 1 | I10: =IF(G10+H10=0,0,2*G10*H10/(G10+H10)) -> 0.18181818 | J10: 0.4 | K10: 1 | L10: 402 | M10: =IF(J10+K10=0,0,ROUND(2*J10*K10/(J10+K10),3)) -> 0.571
A11: Where can my kids go to read? | B11: Play,Cognizance | C11: book,chair,table,bed,sofa,desk | D11: Cognizance,Play,Nursing,Exposition,Laziness,Order,Acquisition,Achievement,Nurturance,Conservance,Toxicity avoidance,Sleep | E11: bed,sofa,private room,kitchen table,table,nightstand,desk,chair,bookshelf,books,book | F11: kitchen,living room,bathroom,bedroom | G11: 0.167 | H11: 1 | I11: =IF(G11+H11=0,0,2*G11*H11/(G11+H11)) -> 0.28620394 | J11: 0.545 | K11: 1 | L11: 321 | M11: =IF(J11+K11=0,0,ROUND(2*J11*K11/(J11+K11),3)) -> 0.706
A12: Where can I put my jacket? | B12: Order,Conservance | C12: closet,hanger | D12: Exhibition,Temperature,Order,Retention,Sexual,Exposition,Injury avoidance,Nursing,Sleep,Hunger,Conservance,Construction,Acquisition,Emission,Thirst,Sensory,Laziness,Play,Nurturance,Achievement | E12: bed,sofa,nightstand,closet,closet drawers,private room,towel rack,hanger,chair,desk,table,bookshelf,coat rack,hook | F12: kitchen,living room,bathroom,bedroom | G12: 0.1 | H12: 1 | I12: =IF(G12+H12=0,0,2*G12*H12/(G12+H12)) -> 0.18181818 | J12: 0.143 | K12: 1 | L12: 424 | M12: =IF(J12+K12=0,0,ROUND(2*J12*K12/(J12+K12),3)) -> 0.25
A13: Where can I wipe my shoes? | B13: Conservance,Order | C13: cleaning sponge,rug | D13: Emission,Injury avoidance,Conservance,Exhibition,Order,Toxicity avoidance,Nurturance,Retention,Sensory,Achievement,Sexual,Exposition,Construction,Thirst,Nursing,Acquisition,Sleep,Laziness,Breathing,Hunger | E13: floor,rug,door,kitchen counter,kitchen table,bathroom counter | F13: kitchen,bathroom,living room,bedroom | G13: 0.1 | H13: 1 | I13: =IF(G13+H13=0,0,2*G13*H13/(G13+H13)) -> 0.18181818 | J13: 0.167 | K13: 0.5 | L13: 397 | M13: =IF(J13+K13=0,0,ROUND(2*J13*K13/(J13+K13),3)) -> 0.25
A14: Where can I put my hat? | B14: Order | C14: closet,closet drawers,hanger,desk,table | D14: Exhibition,Construction,Exposition,Temperature,Sleep,Order,Hunger,Laziness,Play,Achievement,Thirst,Retention,Nursing,Sexual,Acquisition,Injury avoidance,Emission,Conservance,Sensory,Nurturance | E14: bed,nightstand,bookshelf,closet,private room,kitchen table,desk,chair,kitchen counter,table,rug,sofa,pillow,closet drawers,wall picture frame,box,sofa,pile of clothes | F14: kitchen,living room,bathroom,bedroom | G14: 0.05 | H14: 1 | I14: =IF(G14+H14=0,0,2*G14*H14/(G14+H14)) -> 0.095238095 | J14: 0.222 | K14: 0.8 | L14: 437 | M14: =IF(J14+K14=0,0,ROUND(2*J14*K14/(J14+K14),3)) -> 0.348
A15: I want to take a nap. | B15: Sleep,Laziness | C15: bed,chair,sofa,private room,floor | D15: Sleep,Laziness,Play,Nursing,Thirst,Nurturance,Sensory,Hunger,Injury avoidance,Temperature,Achievement,Breathing,Conservance,Emission,Exhibition,Cognizance,Sexual,Order,Exposition,Retention | E15: bed,sofa,pillow,private room,closet,chair,table,desk,rug,ceiling lamp,table lamp,wall,closet drawers,sofa,television,power socket,floor | F15: kitchen,living room,bathroom,bedroom | G15: 0.1 | H15: 1 | I15: =IF(G15+H15=0,0,2*G15*H15/(G15+H15)) -> 0.18181818 | J15: 0.353 | K15: 1 | L15: 432 | M15: =IF(J15+K15=0,0,ROUND(2*J15*K15/(J15+K15),3)) -> 0.522
A16: Where can I sit and eat if I don't want to use the dining table? | B16: Hunger | C16: desk,chair,sofa,private room, kitchen counter, kitchen table | D16: Exposition,Play,Hunger,Cognizance,Achievement,Order,Acquisition,Nursing,Laziness,Sleep,Toxicity avoidance,Conservance,Thirst,Construction,Exhibition,Retention,Sexual,Nurturance,Emission,Temperature | E16: bed,sofa,nightstand,TV stand,desk,chair,rug,sofa | F16: kitchen,living room,bathroom,bedroom | G16: 0.05 | H16: 1 | I16: =IF(G16+H16=0,0,2*G16*H16/(G16+H16)) -> 0.095238095 | J16: 0.5 | K16: 0.5 | L16: 410 | M16: =IF(J16+K16=0,0,ROUND(2*J16*K16/(J16+K16),3)) -> 0.5
A17: Where can I put my apples? | B17: Conservance,Order | C17: wall shelf,kitchen cabinet,kitchen counter,table,desk,kitchen table,dish | D17: Exposition,Hunger,Construction,Acquisition,Order,Sexual,Retention,Exhibition,Play,Laziness,Sleep,Achievement,Sensory,Thirst,Conservance,Nursing,Cognizance,Temperature,Emission,Injury avoidance | E17: bowl of dishes,cabinet,nightstand,dish,bookshelf,closet,kitchen table,table,desk,chair,microwave,kitchen counter,stove,refrigerator,kitchen cabinet,closet drawers,box,coffee maker,oven tray,cooking pot | F17: bedroom,living room,bathroom,kitchen | G17: 0.1 | H17: 1 | I17: =IF(G17+H17=0,0,2*G17*H17/(G17+H17)) -> 0.18181818 | J17: 0.3 | K17: 0.857 | L17: 440 | M17: =IF(J17+K17=0,0,ROUND(2*J17*K17/(J17+K17),3)) -> 0.444
A18: Where can I dry my shoes when I come into the house? | B18: Conservance,Order | C18: rug,floor | D18: Conservance,Injury avoidance,Thirst,Temperature,Retention,Nursing,Order,Play,Exhibition,Sleep,Laziness,Sexual,Acquisition,Sensory,Nurturance,Exposition,Toxicity avoidance,Construction,Emission,Hunger | E18: towel,nightstand,closet,chair,rug,kitchen counter,sink,floor,kitchen table,table,dishwasher,hanger,bathroom counter,sofa,floor shelf | F18: living room,bathroom,kitchen,bedroom | G18: 0.1 | H18: 1 | I18: =IF(G18+H18=0,0,2*G18*H18/(G18+H18)) -> 0.18181818 | J18: 0.133 | K18: 1 | L18: 433 | M18: =IF(J18+K18=0,0,ROUND(2*J18*K18/(J18+K18),3)) -> 0.235
A19: Where can I lay down and read a book? | B19: Laziness,Sleep,Cognizance | C19: bed,sofa,floor,private room | D19: Play,Achievement,Cognizance,Laziness,Acquisition,Exposition,Sleep,Sensory,Nursing,Order,Hunger,Breathing,Construction,Thirst,Temperature,Exhibition,Conservance,Retention,Injury avoidance,Nurturance | E19: bed,sofa,rug,pillow | F19: kitchen,living room,bathroom,bedroom | G19: 0.15 | H19: 1 | I19: =IF(G19+H19=0,0,2*G19*H19/(G19+H19)) -> 0.26086957 | J19: 0.5 | K19: 0.5 | L19: 397 | M19: =IF(J19+K19=0,0,ROUND(2*J19*K19/(J19+K19),3)) -> 0.5
A20: Where can I warm up? | B20: Temperature,Sensory desire | C20: stove,bed | D20: Temperature,Play,Thirst,Injury avoidance,Conservance,Laziness,Hunger,Nursing,Sleep,Breathing,Exhibition,Emission,Sensory,Order,Nurturance,Toxicity avoidance,Exposition,Retention,Acquisition,Cognizance | E20: bed,sofa,TV,nightstand,light switch,towel,toaster,microwave,electric fan,stove,rug,washing machine,ceiling lamp,table lamp,refrigerator,ventilation fan,bathtub,pillow,television,sofa,oven tray,slippers,curtain | F20: kitchen,living room,bathroom,bedroom | G20: 0.05 | H20: 0.5 | I20: =IF(G20+H20=0,0,2*G20*H20/(G20+H20)) -> 0.090909091 | J20: 0.087 | K20: 1 | L20: 449 | M20: =IF(J20+K20=0,0,ROUND(2*J20*K20/(J20+K20),3)) -> 0.16
A21: Where can I get drinking water? | B21: Thirst | C21: sink,water glass,faucet,mug,refrigerator | D21: Thirst,Toxicity avoidance,Conservance,Nursing,Temperature,Breathing,Hunger,Emission,Play,Nurturance,Injury avoidance,Sensory,Achievement,Order,Acquisition,Cognizance,Exposition,Sleep,Exhibition,Retention | E21: sink,faucet,water glass,mug,cup | F21: living room,bathroom,kitchen | G21: 0.05 | H21: 1 | I21: =IF(G21+H21=0,0,2*G21*H21/(G21+H21)) -> 0.095238095 | J21: 0.8 | K21: 0.8 | L21: 394 | M21: =IF(J21+K21=0,0,ROUND(2*J21*K21/(J21+K21),3)) -> 0.8
... A84: I need to fix something and may require a screwdriver,where should I look? | B84: Conservance,Acquisition | C84: wall shelf,cabinet,closet,box | D84: Construction,Conservance,Order,Retention,Sleep,Acquisition,Play,Temperature,Nursing,Cognizance,Thirst,Hunger,Injury avoidance,Sexual,Toxicity avoidance,Exposition,Laziness,Achievement,Exhibition,Sensory | E84: cabinet,bookshelf,closet,kitchen cabinet,closet drawers | F84: kitchen,bathroom,living room,bedroom | G84: 0.1 | H84: 1 | I84: =IF(G84+H84=0,0,2*G84*H84/(G84+H84)) -> 0.18181818 | J84: 0.4 | K84: 0.5 | L84: 405 | M84: =IF(J84+K84=0,0,ROUND(2*J84*K84/(J84+K84),3)) -> 0.444
A85: I have a couple of mails that I would like to deliver through USPS,so where should I put them? | B85: Conservance,Order | C85: box | D85: Order,Acquisition,Nursing,Emission,Conservance,Retention,Exposition,Nurturance,Sexual,Hunger,Thirst,Play,Injury avoidance,Sleep,Sensory,Exhibition,Achievement,Toxicity avoidance,Laziness,Construction | E85: mailbox | G85: 0.1 | H85: 1 | I85: =IF(G85+H85=0,0,2*G85*H85/(G85+H85)) -> 0.18181818 | J85: 0 | K85: 0 | L85: 405 | M85: =IF(J85+K85=0,0,ROUND(2*J85*K85/(J85+K85),3)) -> 0
A86: I need to get rid of the stack of papers on my desk. Where should I put it? | B86: Order,Conservance | C86: wall shelf,garbage,cabinet,bookshelf,box | D86: Emission,Order,Toxicity avoidance,Retention,Injury avoidance,Conservance,Laziness,Play,Exposition,Exhibition,Breathing,Nursing,Achievement,Sensory,Thirst,Sleep,Acquisition,Cognizance,Temperature,Nurturance | E86: cabinet,folder,bookshelf,closet,desk,box | F86: kitchen,bathroom,living room,bedroom | G86: 0.1 | H86: 1 | I86: =IF(G86+H86=0,0,2*G86*H86/(G86+H86)) -> 0.18181818 | J86: 0.5 | K86: 0.6 | L86: 360 | M86: =IF(J86+K86=0,0,ROUND(2*J86*K86/(J86+K86),3)) -> 0.545
A87: Where should I put the wire to charge my computer if I'm sitting at the desk with the backpack on it? | B87: Conservance,Order | C87: desk,computer,power socket,table | D87: Acquisition,Exposition,Achievement,Cognizance,Laziness,Play,Order,Construction,Sleep,Conservance,Thirst,Temperature,Nursing,Retention,Sexual,Hunger,Toxicity avoidance,Nurturance,Exhibition,Emission | E87: power socket | F87: kitchen,bathroom,living room,bedroom | G87: 0.1 | H87: 1 | I87: =IF(G87+H87=0,0,2*G87*H87/(G87+H87)) -> 0.18181818 | J87: 1 | K87: 0.25 | L87: 399 | M87: =IF(J87+K87=0,0,ROUND(2*J87*K87/(J87+K87),3)) -> 0.4
A88: Where did I put my pink shirt? | B88: Acquisition,Conservance,Order | C88: closet,hanger,pile of clothes | D88: Exhibition,Sexual,Order,Exposition,Nursing,Construction,Temperature,Retention,Emission,Sensory,Sleep,Thirst,Acquisition,Injury avoidance,Conservance,Laziness,Hunger,Play,Nurturance,Breathing | E88: closet,private room,closet drawers,hanger,pile of clothes | F88: living room,bathroom,kitchen,bedroom | G88: 0.15 | H88: 1 | I88: =IF(G88+H88=0,0,2*G88*H88/(G88+H88)) -> 0.26086957 | J88: 0.6 | K88: 1 | L88: 404 | M88: =IF(J88+K88=0,0,ROUND(2*J88*K88/(J88+K88),3)) -> 0.75
A89: How can I cool myself off? | B89: Temperature | C89: ventilation fan,electric fan | D89: Temperature,Thirst,Breathing,Laziness,Sensory,Play,Injury avoidance,Sleep,Exhibition,Toxicity avoidance,Hunger,Exposition,Cognizance,Achievement,Conservance,Emission,Sexual,Order,Nursing,Construction | E89: electric fan,water glass,towel,faucet,ventilation fan,bathtub,refrigerator | F89: kitchen,bathroom,living room | G89: 0.05 | H89: 1 | I89: =IF(G89+H89=0,0,2*G89*H89/(G89+H89)) -> 0.095238095 | J89: 0.286 | K89: 1 | L89: 403 | M89: =IF(J89+K89=0,0,ROUND(2*J89*K89/(J89+K89),3)) -> 0.445
A90: After washing my hands in the sink,what should I use to dry my hands? | B90: Conservance,Order | C90: towel,tissue,towel rack | D90: Conservance,Thirst,Toxicity avoidance,Emission,Nursing,Nurturance,Order,Sensory,Exhibition,Retention,Exposition,Play,Temperature,Construction,Achievement,Sleep,Acquisition,Injury avoidance,Hunger,Cognizance | E90: towel,tissue,toilet paper | F90: bathroom,living room | G90: 0.1 | H90: 1 | I90: =IF(G90+H90=0,0,2*G90*H90/(G90+H90)) -> 0.18181818 | J90: 0.667 | K90: 0.667 | L90: 403 | M90: =IF(J90+K90=0,0,ROUND(2*J90*K90/(J90+K90),3)) -> 0.667
A91: Where do I reach for laundry detergent? | B91: Conservance,Acquisition | C91: dishwashing liquid,washing machine,cleaning sponge,bathroom cabinet,cabinet | D91: Conservance,Nursing,Toxicity avoidance,Exhibition,Retention,Sensory,Injury avoidance,Order,Nurturance,Emission,Sexual,Breathing,Laziness,Sleep,Play,Thirst,Temperature,Exposition,Hunger,Achievement | E91: cabinet,kitchen cabinet,bathroom cabinet | F91: kitchen,bathroom,bedroom | G91: 0.05 | H91: 0.5 | I91: =IF(G91+H91=0,0,2*G91*H91/(G91+H91)) -> 0.090909091 | J91: 0.667 | K91: 0.4 | L91: 398 | M91: =IF(J91+K91=0,0,ROUND(2*J91*K91/(J91+K91),3)) -> 0.5
A92: Where could i wash my hands | B92: Toxicity avoidance | C92: sink,soap,faucet | D92: Conservance,Emission,Toxicity avoidance,Nursing,Nurturance,Sensory,Exhibition,Thirst,Exposition,Temperature,Breathing,Retention,Injury avoidance,Order,Play,Sexual,Construction,Sleep,Hunger,Cognizance | E92: toilet,sink,faucet,bathroom cabinet,bathroom counter | F92: bathroom,kitchen | G92: 0.05 | H92: 1 | I92: =IF(G92+H92=0,0,2*G92*H92/(G92+H92)) -> 0.095238095 | J92: 0.4 | K92: 0.667 | L92: 399 | M92: =IF(J92+K92=0,0,ROUND(2*J92*K92/(J92+K92),3)) -> 0.5
A93: What should I do to cool down? | B93: Temperature | C93: ventilation fan,electric fan | D93: Temperature,Thirst,Play,Laziness,Breathing,Sleep,Injury avoidance,Sensory,Hunger,Conservance,Exhibition,Cognizance,Toxicity avoidance,Achievement,Exposition,Emission,Order,Nursing,Sexual,Nurturance | E93: refrigerator,air conditioning,electric fan,faucet,sink,ventilation fan,mug,water glass,bathroom cabinet,bathroom counter,towel rack,bathtub,shower,mirror | F93: living room,bathroom,kitchen | G93: 0.05 | H93: 1 | I93: =IF(G93+H93=0,0,2*G93*H93/(G93+H93)) -> 0.095238095 | J93: 0.143 | K93: 1 | L93: 428 | M93: =IF(J93+K93=0,0,ROUND(2*J93*K93/(J93+K93),3)) -> 0.25
A94: Where do I throw away food packages? | B94: Order | C94: garbage | D94: Hunger,Emission,Conservance,Injury avoidance,Order,Nursing,Nurturance,Exhibition,Sensory,Toxicity avoidance,Retention,Thirst,Play,Sexual,Temperature,Exposition,Sleep,Achievement,Construction,Acquisition | E94: garbage | F94: living room | G94: 0.05 | H94: 1 | I94: =IF(G94+H94=0,0,2*G94*H94/(G94+H94)) -> 0.095238095 | J94: 1 | K94: 1 | L94: 391 | M94: =IF(J94+K94=0,0,ROUND(2*J94*K94/(J94+K94),3)) -> 1

Sheet test_rag_border02_4o
A1: 発話事例 | B1: 欲求の種類 | C1: 正解の物 | D1: rag出力 | E1: 物の出力 | F1: 部屋 | G1: 適合率(欲求) | H1: 再現率(欲求) | I1: F値(欲求) | J1: 適合率(物) | K1: 再現率(物) | L1: トークン数 | M1: F値（物） | N1: 適合率 | O1: 再現率 | P1: F値平均
A2: Is there something to wipe my nose? If so where is it? | B2: Emission,Order | C2: tissue,table,toilet paper | D2: Emission,Breathing,Conservance,Toxicity avoidance,Sensory,Nursing,Exhibition,Thirst,Nurturance,Order,Injury avoidance,Exposition,Sleep,Temperature,Retention | E2: tissue,towel | F2: living room,bathroom | G2: 0.133 | H2: 1 | I2: =IF(G2+H2=0,0,2*G2*H2/(G2+H2)) -> 0.23477493 | J2: 0.5 | K2: 0.333 | L2: 319 | M2: =IF(J2+K2=0,0,ROUND(2*J2*K2/(J2+K2),3)) -> 0.4 | N2: =ROUND(AVERAGE(J2:J94),3) -> 0.539 | O2: =ROUND(AVERAGE(K2:K94),3) -> 0.631 | P2: =SUM(M2:M94)/93 -> 0.54031183
A3: Where can I take a nap? | B3: Laziness,Sleep | C3: bed,chair,sofa,private room,floor | D3: Sleep,Laziness,Play,Nursing,Thirst,Nurturance,Sensory,Hunger,Injury avoidance,Temperature,Achievement,Breathing | E3: bed,sofa,private room,pillow,chair | F3: bedroom,living room,kitchen,bathroom | G3: 0.167 | H3: 1 | I3: =IF(G3+H3=0,0,2*G3*H3/(G3+H3)) -> 0.28620394 | J3: 0.8 | K3: 0.8 | L3: 303 | M3: =IF(J3+K3=0,0,ROUND(2*J3*K3/(J3+K3),3)) -> 0.8
A4: Where can I wash my hands? | B4: Toxicity avoidance | C4: sink,faucet,toilet | D4: Conservance,Emission,Toxicity avoidance,Nursing,Nurturance,Sensory,Exhibition,Thirst | E4: sink,faucet,soap,towel | F4: kitchen,bathroom | G4: 0.125 | H4: 1 | I4: =IF(G4+H4=0,0,2*G4*H4/(G4+H4)) -> 0.22222222 | J4: 0.5 | K4: 0.667 | L4: 235 | M4: =IF(J4+K4=0,0,ROUND(2*J4*K4/(J4+K4),3)) -> 0.572
A5: Where should I store fruits that I want to last long? | B5: Conservance,Order | C5: refrigerator,kitchen cabinet | D5: Hunger,Retention,Conservance,Construction,Order,Thirst | E5: refrigerator,banana,box,kitchen cabinet | F5: kitchen | G5: 0.333 | H5: 1 | I5: =IF(G5+H5=0,0,2*G5*H5/(G5+H5)) -> 0.49962491 | J5: 0.5 | K5: 1 | L5: 318 | M5: =IF(J5+K5=0,0,ROUND(2*J5*K5/(J5+K5),3)) -> 0.667 | N5: =ROUND(AVERAGE(G2:G94),3) -> 0.207 | O5: =ROUND(AVERAGE(H2:H94),3) -> 0.839 | P5: =ROUND(AVERAGE(I2:I94),3) -> 0.291
A6: Where can I take notes? | B6: Cognizance,Exposition | C6: desk,table,computer,mobile phone | D6: Cognizance,Exposition,Sensory,Acquisition,Achievement,Order,Construction,Retention,Exhibition,Conservance,Play,Injury avoidance,Breathing | E6: book,desk,folder,notebook | F6: living room,kitchen | G6: 0.154 | H6: 1 | I6: =IF(G6+H6=0,0,2*G6*H6/(G6+H6)) -> 0.26689775 | J6: 0.25 | K6: 0.25 | L6: 296 | M6: =IF(J6+K6=0,0,ROUND(2*J6*K6/(J6+K6),3)) -> 0.25 | O6: 平均トークン
A7: Where can I brush my teeth? | B7: Conservance,Toxicity avoidance | C7: toothbrush,toothpaste,faucet,sink,toilet | D7: Toxicity avoidance,Conservance,Nursing,Nurturance,Emission,Sleep,Retention,Exhibition,Breathing,Sensory,Injury avoidance,Thirst,Exposition,Order | E7: toothbrush,toothpaste,sink,mirror,bathroom counter | F7: kitchen,bathroom | G7: 0.143 | H7: 1 | I7: =IF(G7+H7=0,0,2*G7*H7/(G7+H7)) -> 0.25021872 | J7: 0.6 | K7: 0.6 | L7: 316 | M7: =IF(J7+K7=0,0,ROUND(2*J7*K7/(J7+K7),3)) -> 0.6 | O7: =AVERAGE(L2:L94) -> 281.58065
A8: Where can I set if I want to warmup? | B8: Temperature | C8: stove,bed | D8: Temperature,Play,Laziness,Injury avoidance,Thirst,Sleep | E8: electric fan,stove,private room | F8: living room,kitchen,bathroom | G8: 0.167 | H8: 1 | I8: =IF(G8+H8=0,0,2*G8*H8/(G8+H8)) -> 0.28620394 | J8: 0.333 | K8: 0.5 | L8: 225 | M8: =IF(J8+K8=0,0,ROUND(2*J8*K8/(J8+K8),3)) -> 0.4 | O8: 標準偏差
A9: Where can I check my appearance? | B9: Order,Exhibition,Exposition | C9: mirror | D9: Exhibition,Construction,Order,Sensory,Sexual,Exposition,Cognizance | E9: mirror,bathroom counter,clothes shirt,clothes pants | F9: bedroom,living room,bathroom | G9: 0.429 | H9: 1 | I9: =IF(G9+H9=0,0,2*G9*H9/(G9+H9)) -> 0.60041987 | J9: 0.25 | K9: 1 | L9: 240 | M9: =IF(J9+K9=0,0,ROUND(2*J9*K9/(J9+K9),3)) -> 0.4 | O9: =_xlfn.STDEV.P(L2:L94) -> 74.881602
A10: Where should I put my jackets? | B10: Order,Conservance | C10: closet,hanger | D10: Exhibition,Temperature,Order | E10: hanger,cabinet,closet,floor shelf,box | F10: kitchen,bedroom,living room,bathroom | G10: 0.333 | H10: 0.5 | I10: =IF(G10+H10=0,0,2*G10*H10/(G10+H10)) -> 0.3997599 | J10: 0.4 | K10: 1 | L10: 220 | M10: =IF(J10+K10=0,0,ROUND(2*J10*K10/(J10+K10),3)) -> 0.571
A11: Where can my kids go to read? | B11: Play,Cognizance | C11: book,chair,table,bed,sofa,desk | D11: Cognizance | E11: book,desk | F11: living room | G11: 1 | H11: 0.5 | I11: =IF(G11+H11=0,0,2*G11*H11/(G11+H11)) -> 0.66666667 | J11: 1 | K11: 0.333 | L11: 119 | M11: =IF(J11+K11=0,0,ROUND(2*J11*K11/(J11+K11),3)) -> 0.5
A12: Where can I put my jacket? | B12: Order,Conservance | C12: closet,hanger | D12: Exhibition,Temperature,Order | E12: hanger,cabinet,pile of clothes,closet,closet drawers | F12: kitchen,bedroom,living room,bathroom | G12: 0.333 | H12: 0.5 | I12: =IF(G12+H12=0,0,2*G12*H12/(G12+H12)) -> 0.3997599 | J12: 0.4 | K12: 1 | L12: 223 | M12: =IF(J12+K12=0,0,ROUND(2*J12*K12/(J12+K12),3)) -> 0.571
A13: Where can I wipe my shoes? | B13: Conservance,Order | C13: cleaning sponge,rug | D13: Emission,Injury avoidance,Conservance,Exhibition,Order,Toxicity avoidance,Nurturance | E13: floor,kitchen table,garage door,mudroom rug | F13: kitchen,bedroom,living room,bathroom | G13: 0.286 | H13: 1 | I13: =IF(G13+H13=0,0,2*G13*H13/(G13+H13)) -> 0.44479005 | J13: 0 | K13: 0 | L13: 261 | M13: =IF(J13+K13=0,0,ROUND(2*J13*K13/(J13+K13),3)) -> 0
A14: Where can I put my hat? | B14: Order | C14: closet,closet drawers,hanger,desk,table | D14: Exhibition,Construction,Exposition | E14: closet,table,desk,closet drawers | F14: kitchen,bedroom,living room,bathroom | G14: 0 | H14: 0 | I14: =IF(G14+H14=0,0,2*G14*H14/(G14+H14)) -> 0 | J14: 1 | K14: 0.8 | L14: 157 | M14: =IF(J14+K14=0,0,ROUND(2*J14*K14/(J14+K14),3)) -> 0.889
A15: I want to take a nap. | B15: Sleep,Laziness | C15: bed,chair,sofa,private room,floor | D15: Sleep,Laziness,Play,Nursing,Thirst,Nurturance,Sensory,Hunger,Injury avoidance,Temperature,Achievement,Breathing | E15: bed,sofa,pillow,private room,nightstand | F15: bedroom,living room,kitchen,bathroom | G15: 0.167 | H15: 1 | I15: =IF(G15+H15=0,0,2*G15*H15/(G15+H15)) -> 0.28620394 | J15: 0.6 | K15: 0.6 | L15: 304 | M15: =IF(J15+K15=0,0,ROUND(2*J15*K15/(J15+K15),3)) -> 0.6
A16: Where can I sit and eat if I don't want to use the dining table? | B16: Hunger | C16: desk,chair,sofa,private room, kitchen counter, kitchen table | D16: Exposition,Play,Hunger,Cognizance,Achievement,Acquisition,Order,Nursing,Laziness,Sleep,Toxicity avoidance,Conservance,Thirst,Construction,Exhibition | E16: sofa,bed,desk,bathtub,chair | F16: bedroom,living room,kitchen,bathroom | G16: 0.067 | H16: 1 | I16: =IF(G16+H16=0,0,2*G16*H16/(G16+H16)) -> 0.12558575 | J16: 0.6 | K16: 0.5 | L16: 393 | M16: =IF(J16+K16=0,0,ROUND(2*J16*K16/(J16+K16),3)) -> 0.545
A17: Where can I put my apples? | B17: Conservance,Order | C17: wall shelf,kitchen cabinet,kitchen counter,table,desk,kitchen table,dish | D17: Exposition,Hunger,Construction,Acquisition,Order,Sexual,Retention,Exhibition,Play,Laziness,Sleep | E17: cabinet,kitchen table,kitchen counter,refrigerator,box | F17: bedroom,kitchen | G17: 0.091 | H17: 0.5 | I17: =IF(G17+H17=0,0,2*G17*H17/(G17+H17)) -> 0.15397631 | J17: 0.4 | K17: 0.286 | L17: 345 | M17: =IF(J17+K17=0,0,ROUND(2*J17*K17/(J17+K17),3)) -> 0.334
A18: Where can I dry my shoes when I come into the house? | B18: Conservance,Order | C18: rug,floor | D18: Conservance,Injury avoidance,Thirst,Temperature,Retention,Order,Nursing,Play,Exhibition,Sleep,Laziness,Sexual,Acquisition,Sensory,Nurturance,Exposition,Toxicity avoidance | E18: towel rack,door,closet,ventilation fan,wall | F18: kitchen,bedroom,living room,bathroom | G18: 0.118 | H18: 1 | I18: =IF(G18+H18=0,0,2*G18*H18/(G18+H18)) -> 0.21109123 | J18: 0 | K18: 0 | L18: 353 | M18: =IF(J18+K18=0,0,ROUND(2*J18*K18/(J18+K18),3)) -> 0
A19: Where can I lay down and read a book? | B19: Laziness,Sleep,Cognizance | C19: bed,sofa,floor,private room | D19: Play,Achievement,Cognizance,Laziness,Acquisition,Exposition | E19: bed,sofa,pillow,floor,chair | F19: bedroom,living room,kitchen,bathroom | G19: 0.333 | H19: 0.667 | I19: =IF(G19+H19=0,0,2*G19*H19/(G19+H19)) -> 0.444222 | J19: 0.6 | K19: 0.75 | L19: 174 | M19: =IF(J19+K19=0,0,ROUND(2*J19*K19/(J19+K19),3)) -> 0.667
A20: Where can I warm up? | B20: Temperature,Sensory desire | C20: stove,bed | D20: Temperature,Play,Thirst,Injury avoidance,Conservance,Laziness | E20: refrigerator,coffee maker,stove,electric fan,bathtub,slippers,mug,private room,chair | F20: bedroom,living room,kitchen,bathroom | G20: 0.167 | H20: 0.5 | I20: =IF(G20+H20=0,0,2*G20*H20/(G20+H20)) -> 0.25037481 | J20: 0.111 | K20: 0.5 | L20: 261 | M20: =IF(J20+K20=0,0,ROUND(2*J20*K20/(J20+K20),3)) -> 0.182
A21: Where can I get drinking water? | B21: Thirst | C21: sink,water glass,faucet,mug,refrigerator | D21: Thirst,Toxicity avoidance,Conservance,Nursing,Temperature,Breathing,Hunger,Emission,Play | E21: sink,water glass,faucet,refrigerator | F21: kitchen,living room,bathroom | G21: 0.111 | H21: 1 | I21: =IF(G21+H21=0,0,2*G21*H21/(G21+H21)) -> 0.19981998 | J21: 1 | K21: 0.8 | L21: 298 | M21: =IF(J21+K21=0,0,ROUND(2*J21*K21/(J21+K21),3)) -> 0.889
... A84: I need to fix something and may require a screwdriver,where should I look? | B84: Conservance,Acquisition | C84: wall shelf,cabinet,closet,box | D84: Construction,Conservance,Retention,Order,Sleep,Acquisition,Play,Temperature,Nursing,Cognizance,Thirst,Hunger,Injury avoidance | E84: cabinet,closet,kitchen cabinet,desk,box | F84: kitchen,bedroom,living room,bathroom | G84: 0.154 | H84: 1 | I84: =IF(G84+H84=0,0,2*G84*H84/(G84+H84)) -> 0.26689775 | J84: 0.6 | K84: 0.75 | L84: 392 | M84: =IF(J84+K84=0,0,ROUND(2*J84*K84/(J84+K84),3)) -> 0.667
A85: I have a couple of mails that I would like to deliver through USPS,so where should I put them? | B85: Conservance,Order | C85: box | D85: [none] | E85: mailbox,post office | G85: 0 | H85: 0 | I85: =IF(G85+H85=0,0,2*G85*H85/(G85+H85)) -> 0 | J85: 0 | K85: 0 | L85: 118 | M85: =IF(J85+K85=0,0,ROUND(2*J85*K85/(J85+K85),3)) -> 0
A86: I need to get rid of the stack of papers on my desk. Where should I put it? | B86: Order,Conservance | C86: wall shelf,garbage,cabinet,bookshelf,box | D86: Emission,Order,Toxicity avoidance,Retention,Injury avoidance | E86: folder,box,bookshelf,garbage | F86: living room,kitchen | G86: 0.2 | H86: 0.5 | I86: =IF(G86+H86=0,0,2*G86*H86/(G86+H86)) -> 0.28571429 | J86: 0.75 | K86: 0.6 | L86: 230 | M86: =IF(J86+K86=0,0,ROUND(2*J86*K86/(J86+K86),3)) -> 0.667
A87: Where should I put the wire to charge my computer if I'm sitting at the desk with the backpack on it? | B87: Conservance,Order | C87: desk,computer,power socket,table | D87: Acquisition,Exposition,Achievement,Cognizance,Laziness,Play,Order,Construction,Sleep,Conservance,Thirst,Temperature,Retention,Nursing,Sexual | E87: desk,power socket,computer | F87: kitchen,bedroom,living room,bathroom | G87: 0.133 | H87: 1 | I87: =IF(G87+H87=0,0,2*G87*H87/(G87+H87)) -> 0.23477493 | J87: 1 | K87: 0.75 | L87: 339 | M87: =IF(J87+K87=0,0,ROUND(2*J87*K87/(J87+K87),3)) -> 0.857
A88: Where did I put my pink shirt? | B88: Acquisition,Conservance,Order | C88: closet,hanger,pile of clothes | D88: Exhibition,Sexual,Order,Exposition,Nursing | E88: hanger,closet,pile of clothes,nightstand,clothes shirt | F88: kitchen,bedroom,living room,bathroom | G88: 0.2 | H88: 0.333 | I88: =IF(G88+H88=0,0,2*G88*H88/(G88+H88)) -> 0.24990619 | J88: 0.6 | K88: 1 | L88: 239 | M88: =IF(J88+K88=0,0,ROUND(2*J88*K88/(J88+K88),3)) -> 0.75
A89: How can I cool myself off? | B89: Temperature | C89: ventilation fan,electric fan | D89: Temperature,Thirst,Breathing,Laziness,Sensory,Play,Injury avoidance | E89: ventilation fan,refrigerator,electric fan,water glass,sink,faucet,bathtub | F89: living room,kitchen,bathroom | G89: 0.143 | H89: 1 | I89: =IF(G89+H89=0,0,2*G89*H89/(G89+H89)) -> 0.25021872 | J89: 0.286 | K89: 1 | L89: 217 | M89: =IF(J89+K89=0,0,ROUND(2*J89*K89/(J89+K89),3)) -> 0.445
A90: After washing my hands in the sink,what should I use to dry my hands? | B90: Conservance,Order | C90: towel,tissue,towel rack | D90: Conservance,Thirst,Toxicity avoidance,Emission,Nursing,Nurturance,Order,Sensory,Exhibition,Retention,Exposition,Play,Temperature,Construction,Achievement,Sleep,Acquisition,Injury avoidance,Hunger,Cognizance | E90: towel | F90: bathroom | G90: 0.1 | H90: 1 | I90: =IF(G90+H90=0,0,2*G90*H90/(G90+H90)) -> 0.18181818 | J90: 1 | K90: 0.333 | L90: 398 | M90: =IF(J90+K90=0,0,ROUND(2*J90*K90/(J90+K90),3)) -> 0.5
A91: Where do I reach for laundry detergent? | B91: Conservance,Acquisition | C91: dishwashing liquid,washing machine,cleaning sponge,bathroom cabinet,cabinet | D91: Conservance,Nursing,Toxicity avoidance,Exhibition,Retention,Sensory,Injury avoidance,Nurturance,Order,Emission,Sexual | E91: kitchen cabinet,washing machine | F91: kitchen,bathroom | G91: 0.091 | H91: 0.5 | I91: =IF(G91+H91=0,0,2*G91*H91/(G91+H91)) -> 0.15397631 | J91: 0.5 | K91: 0.2 | L91: 281 | M91: =IF(J91+K91=0,0,ROUND(2*J91*K91/(J91+K91),3)) -> 0.286
A92: Where could i wash my hands | B92: Toxicity avoidance | C92: sink,soap,faucet | D92: Conservance,Emission,Toxicity avoidance,Nursing,Nurturance,Sensory,Exhibition,Thirst | E92: sink,faucet,soap,towel | F92: kitchen,bathroom | G92: 0.125 | H92: 1 | I92: =IF(G92+H92=0,0,2*G92*H92/(G92+H92)) -> 0.22222222 | J92: 0.75 | K92: 1 | L92: 234 | M92: =IF(J92+K92=0,0,ROUND(2*J92*K92/(J92+K92),3)) -> 0.857
A93: What should I do to cool down? | B93: Temperature | C93: ventilation fan,electric fan | D93: Temperature,Thirst,Play,Laziness,Breathing,Injury avoidance,Sleep,Sensory | E93: ventilation fan,refrigerator,electric fan,bathtub,faucet | F93: living room,kitchen,bathroom | G93: 0.125 | H93: 1 | I93: =IF(G93+H93=0,0,2*G93*H93/(G93+H93)) -> 0.22222222 | J93: 0.4 | K93: 1 | L93: 234 | M93: =IF(J93+K93=0,0,ROUND(2*J93*K93/(J93+K93),3)) -> 0.571
A94: Where do I throw away food packages? | B94: Order | C94: garbage | D94: Hunger,Emission,Conservance,Injury avoidance,Order,Nursing,Nurturance,Exhibition | E94: garbage | F94: living room | G94: 0.125 | H94: 1 | I94: =IF(G94+H94=0,0,2*G94*H94/(G94+H94)) -> 0.22222222 | J94: 1 | K94: 1 | L94: 318 | M94: =IF(J94+K94=0,0,ROUND(2*J94*K94/(J94+K94),3)) -> 1

Sheet test_rag_border03_4o
A1: 発話事例 | B1: 欲求の種類 | C1: 正解の物 | D1: rag出力 | E1: 物の出力 | F1: 部屋 | G1: 適合率(欲求) | H1: 再現率(欲求) | I1: F値(欲求) | J1: 適合率(物) | K1: 再現率(物) | L1: トークン数 | M1: F値（物） | N1: 適合率 | O1: 再現率 | P1: F値平均
A2: Is there something to wipe my nose? If so where is it? | B2: Emission,Order | C2: tissue,table,toilet paper | D2: Emission,Breathing | E2: toilet paper,tissue | F2: bathroom,living room | G2: 0.5 | H2: 0.5 | I2: =IF(G2+H2=0,0,2*G2*H2/(G2+H2)) -> 0.5 | J2: 1 | K2: 0.667 | L2: 129 | M2: =IF(J2+K2=0,0,ROUND(2*J2*K2/(J2+K2),3)) -> 0.8 | N2: =ROUND(AVERAGE(J2:J94),3) -> 0.395 | O2: =ROUND(AVERAGE(K2:K94),3) -> 0.496 | P2: =SUM(M2:M94)/93 -> 0.40022581
A3: Where can I take a nap? | B3: Laziness,Sleep | C3: bed,chair,sofa,private room,floor | D3: Sleep,Laziness,Play | E3: bed,rug,private room,sofa,floor,chair | F3: kitchen,bathroom,living room,bedroom | G3: 0.667 | H3: 1 | I3: =IF(G3+H3=0,0,2*G3*H3/(G3+H3)) -> 0.80023995 | J3: 0.833 | K3: 1 | L3: 192 | M3: =IF(J3+K3=0,0,ROUND(2*J3*K3/(J3+K3),3)) -> 0.909
A4: Where can I wash my hands? | B4: Toxicity avoidance | C4: sink,faucet,toilet | D4: [none] | E4: sink,bathroom,kitchen,cafeteria,hand sanitiser station,restroom | F4: bathroom,kitchen | G4: 0 | H4: 0 | I4: =IF(G4+H4=0,0,2*G4*H4/(G4+H4)) -> 0 | J4: 0.167 | K4: 0.333 | L4: 116 | M4: =IF(J4+K4=0,0,ROUND(2*J4*K4/(J4+K4),3)) -> 0.222
A5: Where should I store fruits that I want to last long? | B5: Conservance,Order | C5: refrigerator,kitchen cabinet | D5: Hunger | E5: refrigerator | F5: kitchen | G5: 0 | H5: 0 | I5: =IF(G5+H5=0,0,2*G5*H5/(G5+H5)) -> 0 | J5: 1 | K5: 0.5 | L5: 169 | M5: =IF(J5+K5=0,0,ROUND(2*J5*K5/(J5+K5),3)) -> 0.667 | N5: =ROUND(AVERAGE(G2:G94),3) -> 0.309 | O5: =ROUND(AVERAGE(H2:H94),3) -> 0.369 | P5: =ROUND(AVERAGE(I2:I94),3) -> 0.308
A6: Where can I take notes? | B6: Cognizance,Exposition | C6: desk,table,computer,mobile phone | D6: [none] | E6: notebook,smartphone,laptop,tablet,journal,whiteboard,sticky notes,desktop computer,blackboard,notepad | G6: 0 | H6: 0 | I6: =IF(G6+H6=0,0,2*G6*H6/(G6+H6)) -> 0 | J6: 0 | K6: 0 | L6: 123 | M6: =IF(J6+K6=0,0,ROUND(2*J6*K6/(J6+K6),3)) -> 0 | O6: 平均トークン
A7: Where can I brush my teeth? | B7: Conservance,Toxicity avoidance | C7: toothbrush,toothpaste,faucet,sink,toilet | D7: Toxicity avoidance | E7: sink,faucet | F7: bathroom,kitchen | G7: 1 | H7: 0.5 | I7: =IF(G7+H7=0,0,2*G7*H7/(G7+H7)) -> 0.66666667 | J7: 1 | K7: 0.4 | L7: 131 | M7: =IF(J7+K7=0,0,ROUND(2*J7*K7/(J7+K7),3)) -> 0.571 | O7: =AVERAGE(L2:L94) -> 155.86022
A8: Where can I set if I want to warmup? | B8: Temperature | C8: stove,bed | D8: Temperature | E8: electric fan,stove | F8: kitchen,living room | G8: 1 | H8: 1 | I8: =IF(G8+H8=0,0,2*G8*H8/(G8+H8)) -> 1 | J8: 0.5 | K8: 0.5 | L8: 132 | M8: =IF(J8+K8=0,0,ROUND(2*J8*K8/(J8+K8),3)) -> 0.5 | O8: 標準偏差
A9: Where can I check my appearance? | B9: Order,Exhibition,Exposition | C9: mirror | D9: Exhibition | E9: mirror,mobile phone | F9: living room,bathroom,kitchen | G9: 1 | H9: 0.333 | I9: =IF(G9+H9=0,0,2*G9*H9/(G9+H9)) -> 0.49962491 | J9: 0.5 | K9: 1 | L9: 138 | M9: =IF(J9+K9=0,0,ROUND(2*J9*K9/(J9+K9),3)) -> 0.667 | O9: =_xlfn.STDEV.P(L2:L94) -> 41.60221
A10: Where should I put my jackets? | B10: Order,Conservance | C10: closet,hanger | D10: [none] | E10: closet,coat rack,wardrobe,hanger,mudroom,entryway,hook,peg | F10: living room,bathroom,bedroom | G10: 0 | H10: 0 | I10: =IF(G10+H10=0,0,2*G10*H10/(G10+H10)) -> 0 | J10: 0.25 | K10: 1 | L10: 118 | M10: =IF(J10+K10=0,0,ROUND(2*J10*K10/(J10+K10),3)) -> 0.4
A11: Where can my kids go to read? | B11: Play,Cognizance | C11: book,chair,table,bed,sofa,desk | D11: [none] | E11: library,bookstore,school,home,park | G11: 0 | H11: 0 | I11: =IF(G11+H11=0,0,2*G11*H11/(G11+H11)) -> 0 | J11: 0 | K11: 0 | L11: 109 | M11: =IF(J11+K11=0,0,ROUND(2*J11*K11/(J11+K11),3)) -> 0
A12: Where can I put my jacket? | B12: Order,Conservance | C12: closet,hanger | D12: [none] | E12: closet,coat rack,hook,chair,bench,table,basket,wardrobe,armchair,dresser,dining chair | F12: living room,bathroom,kitchen,bedroom | G12: 0 | H12: 0 | I12: =IF(G12+H12=0,0,2*G12*H12/(G12+H12)) -> 0 | J12: 0.091 | K12: 0.5 | L12: 124 | M12: =IF(J12+K12=0,0,ROUND(2*J12*K12/(J12+K12),3)) -> 0.154
A13: Where can I wipe my shoes? | B13: Conservance,Order | C13: cleaning sponge,rug | D13: Emission | E13: tissue,toilet paper | F13: bathroom,living room | G13: 0 | H13: 0 | I13: =IF(G13+H13=0,0,2*G13*H13/(G13+H13)) -> 0 | J13: 0 | K13: 0 | L13: 112 | M13: =IF(J13+K13=0,0,ROUND(2*J13*K13/(J13+K13),3)) -> 0
A14: Where can I put my hat? | B14: Order | C14: closet,closet drawers,hanger,desk,table | D14: [none] | E14: hat rack,coat rack,hall tree,closet,hook,table,chair,shelf | F14: living room,bathroom,kitchen,bedroom | G14: 0 | H14: 0 | I14: =IF(G14+H14=0,0,2*G14*H14/(G14+H14)) -> 0 | J14: 0.25 | K14: 0.4 | L14: 117 | M14: =IF(J14+K14=0,0,ROUND(2*J14*K14/(J14+K14),3)) -> 0.308
A15: I want to take a nap. | B15: Sleep,Laziness | C15: bed,chair,sofa,private room,floor | D15: Sleep,Laziness,Play | E15: bed,pillow,rug,private room,sofa,nightstand,floor,curtain | F15: kitchen,living room,bathroom,bedroom | G15: 0.667 | H15: 1 | I15: =IF(G15+H15=0,0,2*G15*H15/(G15+H15)) -> 0.80023995 | J15: 0.5 | K15: 0.8 | L15: 198 | M15: =IF(J15+K15=0,0,ROUND(2*J15*K15/(J15+K15),3)) -> 0.615
A16: Where can I sit and eat if I don't want to use the dining table? | B16: Hunger | C16: desk,chair,sofa,private room, kitchen counter, kitchen table | D16: Exposition,Play,Hunger,Cognizance | E16: sofa,chair,floor,desk,private room,nightstand | F16: kitchen,living room,bathroom,bedroom | G16: 0.25 | H16: 1 | I16: =IF(G16+H16=0,0,2*G16*H16/(G16+H16)) -> 0.4 | J16: 0.667 | K16: 0.667 | L16: 233 | M16: =IF(J16+K16=0,0,ROUND(2*J16*K16/(J16+K16),3)) -> 0.667
A17: Where can I put my apples? | B17: Conservance,Order | C17: wall shelf,kitchen cabinet,kitchen counter,table,desk,kitchen table,dish | D17: [none] | E17: To help you determine where you can put your apples, I need the list of possible objects to consider. Please provide the list so I can assist you further! | G17: 0 | H17: 0 | I17: =IF(G17+H17=0,0,2*G17*H17/(G17+H17)) -> 0 | J17: 0 | K17: 0 | L17: 130 | M17: =IF(J17+K17=0,0,ROUND(2*J17*K17/(J17+K17),3)) -> 0
A18: Where can I dry my shoes when I come into the house? | B18: Conservance,Order | C18: rug,floor | D18: Conservance,Injury avoidance | E18: rug,washing machine,hanger socket,ventilation fan,towel | F18: kitchen,bathroom,living room,bedroom | G18: 0.5 | H18: 0.5 | I18: =IF(G18+H18=0,0,2*G18*H18/(G18+H18)) -> 0.5 | J18: 0.2 | K18: 0.5 | L18: 188 | M18: =IF(J18+K18=0,0,ROUND(2*J18*K18/(J18+K18),3)) -> 0.286
A19: Where can I lay down and read a book? | B19: Laziness,Sleep,Cognizance | C19: bed,sofa,floor,private room | D19: [none] | E19: bed,sofa,hammock,chaise longue,lounge chair,bean bag,recliner,sun lounger,grass,blanket | F19: kitchen,living room,bedroom | G19: 0 | H19: 0 | I19: =IF(G19+H19=0,0,2*G19*H19/(G19+H19)) -> 0 | J19: 0.2 | K19: 0.5 | L19: 130 | M19: =IF(J19+K19=0,0,ROUND(2*J19*K19/(J19+K19),3)) -> 0.286
A20: Where can I warm up? | B20: Temperature,Sensory desire | C20: stove,bed | D20: Temperature | E20: bathtub,stove,coffee maker | F20: bathroom,kitchen | G20: 1 | H20: 0.5 | I20: =IF(G20+H20=0,0,2*G20*H20/(G20+H20)) -> 0.66666667 | J20: 0.333 | K20: 0.5 | L20: 130 | M20: =IF(J20+K20=0,0,ROUND(2*J20*K20/(J20+K20),3)) -> 0.4
A21: Where can I get drinking water? | B21: Thirst | C21: sink,water glass,faucet,mug,refrigerator | D21: Thirst,Toxicity avoidance | E21: sink,refrigerator,water glass,faucet | F21: living room,bathroom,kitchen | G21: 0.5 | H21: 1 | I21: =IF(G21+H21=0,0,2*G21*H21/(G21+H21)) -> 0.66666667 | J21: 1 | K21: 0.8 | L21: 153 | M21: =IF(J21+K21=0,0,ROUND(2*J21*K21/(J21+K21),3)) -> 0.889
A22: Where can I wash my hands on the second story of the house? | B22: Order,Toxicity avoidance,Emission | C22: sink,soap,faucet,toilet | D22: Conservance | E22: faucet,sink,soap | F22: bathroom,kitchen | G22: 0 | H22: 0 | I22: =IF(G22+H22=0,0,2*G22*H22/(G22+H22)) -> 0 | J22: 1 | K22: 0.75 | L22: 174 | M22: =IF(J22+K22=0,0,ROUND(2*J22*K22/(J22+K22),3)) -> 0.857
A23: Where can I hang my towel so I don't have to leave the shower to dry off? | B23: Order | C23: towel rack,hanger | D23: Conservance,Exhibition,Retention | E23: faucet,bathtub | F23: bathroom,kitchen | G23: 0 | H23: 0 | I23: =IF(G23+H23=0,0,2*G23*H23/(G23+H23)) -> 0 | J23: 0 | K23: 0 | L23: 213 | M23: =IF(J23+K23=0,0,ROUND(2*J23*K23/(J23+K23),3)) -> 0
A24: where can I keep a photo frame? | B24: Conservance,Order | C24: wall picture frame,wall shelf,desk,table | D24: Construction,Retention,Order | E24: wall,kitchen table,cabinet,towel rack,bathroom counter,kitchen cabinet,wall,TV stand,mirror,floor shelf,kitchen counter,bookshelf | F24: kitchen,bathroom,living room,bedroom | G24: 0.333 | H24: 0.5 | I24: =IF(G24+H24=0,0,2*G24*H24/(G24+H24)) -> 0.3997599 | J24: 0 | K24: 0 | L24: 228 | M24: =IF(J24+K24=0,0,ROUND(2*J24*K24/(J24+K24),3)) -> 0
A25: where can I keep a couple of apples? | B25: Retention,Conservance,Order | C25: wall shelf,kitchen cabinet,kitchen counter,table,desk,refrigerator | D25: Retention | E25: closet,closet drawers,refrigerator | F25: living room,bathroom,kitchen,bedroom | G25: 1 | H25: 0.333 | I25: =IF(G25+H25=0,0,2*G25*H25/(G25+H25)) -> 0.49962491 | J25: 0.333 | K25: 0.167 | L25: 147 | M25: =IF(J25+K25=0,0,ROUND(2*J25*K25/(J25+K25),3)) -> 0.222
A26: where can I keep a new ironed shirt? | B26: Conservance,Order | C26: closet,hanger | D26: [none] | E26: hanger,closet,wardrobe,dresser,clothes rack,shelf | F26: living room,bathroom,bedroom | G26: 0 | H26: 0 | I26: =IF(G26+H26=0,0,2*G26*H26/(G26+H26)) -> 0 | J26: 0.333 | K26: 1 | L26: 116 | M26: =IF(J26+K26=0,0,ROUND(2*J26*K26/(J26+K26),3)) -> 0.5
A27: where can I sit? | B27: Laziness | C27: chair,sofa,bed,rug | D27: [none] | E27: Chair,Sofa,Stool,Bench,Rocking Chair,Armchair,Recliner,Couch,Ottoman,Futon,Pouffe,Bean Bag,Hammock,Deck Chair,Park Bench,Bar Stool,Chaise Longue | G27: 0 | H27: 0 | I27: =IF(G27+H27=0,0,2*G27*H27/(G27+H27)) -> 0 | J27: 0 | K27: 0 | L27: 145 | M27: =IF(J27+K27=0,0,ROUND(2*J27*K27/(J27+K27),3)) -> 0
A28: where can I keep the keyboard | B28: Order | C28: desk,table | D28: [none] | E28: desk,table,drawer,shelf,cabinet | F28: kitchen,bedroom,living room | G28: 0 | H28: 0 | I28: =IF(G28+H28=0,0,2*G28*H28/(G28+H28)) -> 0 | J28: 0.4 | K28: 1 | L28: 107 | M28: =IF(J28+K28=0,0,ROUND(2*J28*K28/(J28+K28),3)) -> 0.571
A29: where can I keep a small container with chalks? | B29: Order | C29: desk,box,table | D29: Retention,Conservance | E29: closet,closet drawers | F29: living room,bathroom,bedroom | G29: 0 | H29: 0 | I29: =IF(G29+H29=0,0,2*G29*H29/(G29+H29)) -> 0 | J29: 0 | K29: 0 | L29: 188 | M29: =IF(J29+K29=0,0,ROUND(2*J29*K29/(J29+K29),3)) -> 0
A30: where can I store clothes? | B30: Order,Conservance,Retention | C30: closet,closet drawers,hanger | D30: Retention,Conservance,Exhibition,Order | E30: closet,box,cabinet,kitchen cabinet,hanger,closet drawers,TV stand,floor shelf,bookshelf | F30: living room,bathroom,kitchen,bedroom | G30: 0.75 | H30: 1 | I30: =IF(G30+H30=0,0,2*G30*H30/(G30+H30)) -> 0.85714286 | J30: 0.333 | K30: 1 | L30: 260 | M30: =IF(J30+K30=0,0,ROUND(2*J30*K30/(J30+K30),3)) -> 0.5
A31: where can I store books | B31: Order,Conservance,Retention | C31: wall shelf,bookshelf | D31: Retention,Acquisition | E31: closet,folder,table,closet drawers,desk | F31: living room,bathroom,kitchen,bedroom | G31: 0.5 | H31: 0.333 | I31: =IF(G31+H31=0,0,2*G31*H31/(G31+H31)) -> 0.3997599 | J31: 0 | K31: 0 | L31: 163 | M31: =IF(J31+K31=0,0,ROUND(2*J31*K31/(J31+K31),3)) -> 0
A32: Where can I place a glass of water? | B32: Order,Conservance,Thirst | C32: table,desk,kitchen counter,sink,refrigerator | D32: Thirst,Construction | E32: mug,sink,coffee pot,refrigerator,wine glass,water glass,coffee maker | F32: living room,bathroom,kitchen | G32: 0.5 | H32: 0.333 | I32: =IF(G32+H32=0,0,2*G32*H32/(G32+H32)) -> 0.3997599 | J32: 0.286 | K32: 0.4 | L32: 153 | M32: =IF(J32+K32=0,0,ROUND(2*J32*K32/(J32+K32),3)) -> 0.334
A33: Where can I relax and watch TV | B33: Laziness,Play | C33: chair,sofa,TV,television,bed | D33: [none] | E33: sofa,armchair,bed,lounge chair,recliner,couch,love seat | F33: kitchen,living room,bedroom | G33: 0 | H33: 0 | I33: =IF(G33+H33=0,0,2*G33*H33/(G33+H33)) -> 0 | J33: 0.286 | K33: 0.4 | L33: 116 | M33: =IF(J33+K33=0,0,ROUND(2*J33*K33/(J33+K33),3)) -> 0.334
A34: where can i find something to drink | B34: Thirst | C34: sink,faucet,refrigerator,table,desk | D34: Thirst,Hunger | E34: coffee pot,water glass,coffee maker,refrigerator,faucet,mug,wine glass,sink | F34: living room,bathroom,kitchen | G34: 0.5 | H34: 1 | I34: =IF(G34+H34=0,0,2*G34*H34/(G34+H34)) -> 0.66666667 | J34: 0.375 | K34: 0.6 | L34: 198 | M34: =IF(J34+K34=0,0,ROUND(2*J34*K34/(J34+K34),3)) -> 0.462
A35: Where can i relax a bit | B35: Laziness,Sleep | C35: chair,bed,rug,sofa,bathtub,private room | D35: Play,Laziness,Sleep | E35: bed,pillow,rug,private room,table lamp,wall lamp,nightstand,sofa,books,book,chair,electric fan,bathtub | F35: kitchen,living room,bathroom,bedroom | G35: 0.667 | H35: 1 | I35: =IF(G35+H35=0,0,2*G35*H35/(G35+H35)) -> 0.80023995 | J35: 0.462 | K35: 1 | L35: 210 | M35: =IF(J35+K35=0,0,ROUND(2*J35*K35/(J35+K35),3)) -> 0.632
A36: Where can I use the bathroom? | B36: Emission | C36: toilet | D36: Emission,Nursing,Toxicity avoidance,Conservance,Play | E36: toilet,private room,toilet paper,faucet,sink,soap,bathtub | F36: bathroom,kitchen | G36: 0.2 | H36: 1 | I36: =IF(G36+H36=0,0,2*G36*H36/(G36+H36)) -> 0.33333333 | J36: 0.143 | K36: 1 | L36: 232 | M36: =IF(J36+K36=0,0,ROUND(2*J36*K36/(J36+K36),3)) -> 0.25
A37: Where can I clean fruit while facing the dining room table? | B37: Toxicity avoidance,Order | C37: sink,kitchen counter | D37: Order,Conservance,Exposition,Toxicity avoidance | E37: kitchen table,kitchen counter | F37: kitchen | G37: 0.5 | H37: 1 | I37: =IF(G37+H37=0,0,2*G37*H37/(G37+H37)) -> 0.66666667 | J37: 0.5 | K37: 0.5 | L37: 232 | M37: =IF(J37+K37=0,0,ROUND(2*J37*K37/(J37+K37),3)) -> 0.5
A38: Where can I put my scarf? | B38: Order | C38: closet,hanger,closet drawers | D38: [none] | E38: Here is a list of objects where you can put your scarf: coat rack,drawer,hat rack,box,wardrobe,closet,shelf,dresser,hanger,basket | F38: bedroom,bathroom,living room,kitchen | G38: 0 | H38: 0 | I38: =IF(G38+H38=0,0,2*G38*H38/(G38+H38)) -> 0 | J38: 0.2 | K38: 0.667 | L38: 135 | M38: =IF(J38+K38=0,0,ROUND(2*J38*K38/(J38+K38),3)) -> 0.308
A39: Where can I find the time? | B39: Order,Cognizance | C39: TV,cell phone,computer | D39: [none] | E39: clock,watch,smartphone | G39: 0 | H39: 0 | I39: =IF(G39+H39=0,0,2*G39*H39/(G39+H39)) -> 0 | J39: 0 | K39: 0 | L39: 104 | M39: =IF(J39+K39=0,0,ROUND(2*J39*K39/(J39+K39),3)) -> 0
A40: Where can I watch a movie? | B40: Play | C40: TV,sofa,chair,television | D40: Play | E40: TV,sofa,mobile phone,television,private room | F40: bedroom,living room,bathroom,kitchen | G40: 1 | H40: 1 | I40: =IF(G40+H40=0,0,2*G40*H40/(G40+H40)) -> 1 | J40: 0.6 | K40: 0.75 | L40: 155 | M40: =IF(J40+K40=0,0,ROUND(2*J40*K40/(J40+K40),3)) -> 0.667
...

Sheet test_rag_border01
A1: 発話事例 | B1: 欲求の種類 | C1: 正解の物 | D1: rag出力 | E1: 物の出力 | F1: 部屋 | G1: 適合率(欲求) | H1: 再現率(欲求) | I1: F値(欲求) | J1: 適合率(物) | K1: 再現率(物) | L1: トークン数 | M1: F値（物） | N1: 適合率 | O1: 再現率 | P1: F値平均
A2: Is there something to wipe my nose? If so where is it? | B2: Emission,Order | C2: tissue,table,toilet paper | D2: Emission,Breathing,Conservance,Sensory,Toxicity avoidance,Nursing,Exhibition,Thirst,Nurturance,Order,Exposition,Injury avoidance,Sleep,Temperature,Retention,Construction,Achievement,Sexual,Laziness,Cognizance | E2: tissue | F2: living room | G2: 0.1 | H2: 1 | I2: =IF(G2+H2=0,0,2*G2*H2/(G2+H2)) -> 0.18181818 | J2: 1 | K2: 0.333 | L2: 338 | M2: =IF(J2+K2=0,0,ROUND(2*J2*K2/(J2+K2),3)) -> 0.5 | N2: =ROUND(AVERAGE(J2:J94),3) -> 0.549 | O2: =ROUND(AVERAGE(K2:K94),3) -> 0.593 | P2: =SUM(M2:M94)/93 -> 0.527
A3: Where can I take a nap? | B3: Laziness,Sleep | C3: bed,chair,sofa,private room,floor | D3: Sleep,Laziness,Play,Nursing,Thirst,Nurturance,Sensory,Hunger,Injury avoidance,Temperature,Achievement,Breathing,Conservance,Emission,Exhibition,Cognizance,Sexual,Order,Exposition,Retention | E3: bed,sofa,private room | F3: living room,bedroom,bathroom,kitchen | G3: 0.1 | H3: 1 | I3: =IF(G3+H3=0,0,2*G3*H3/(G3+H3)) -> 0.18181818 | J3: 1 | K3: 0.6 | L3: 395 | M3: =IF(J3+K3=0,0,ROUND(2*J3*K3/(J3+K3),3)) -> 0.75
A4: Where can I wash my hands? | B4: Toxicity avoidance | C4: sink,faucet,toilet | D4: Conservance,Emission,Toxicity avoidance,Nursing,Nurturance,Sensory,Exhibition,Thirst,Temperature,Exposition,Breathing,Retention,Injury avoidance,Order,Play,Sexual,Construction,Sleep,Hunger,Cognizance | E4: bathroom counter,towel,sink,soap | F4: bathroom,kitchen | G4: 0.05 | H4: 1 | I4: =IF(G4+H4=0,0,2*G4*H4/(G4+H4)) -> 0.095238095 | J4: 0.25 | K4: 0.333 | L4: 394 | M4: =IF(J4+K4=0,0,ROUND(2*J4*K4/(J4+K4),3)) -> 0.286
A5: Where should I store fruits that I want to last long? | B5: Conservance,Order | C5: refrigerator,kitchen cabinet | D5: Hunger,Retention,Conservance,Order,Construction,Thirst,Nursing,Exhibition,Nurturance,Acquisition,Sleep,Sensory,Injury avoidance,Play,Sexual,Temperature,Laziness,Toxicity avoidance,Achievement,Exposition | E5: refrigerator,kitchen cabinet,bowl of dishes | F5: kitchen | G5: 0.1 | H5: 1 | I5: =IF(G5+H5=0,0,2*G5*H5/(G5+H5)) -> 0.18181818 | J5: 0.667 | K5: 1 | L5: 401 | M5: =IF(J5+K5=0,0,ROUND(2*J5*K5/(J5+K5),3)) -> 0.8 | N5: =ROUND(AVERAGE(G2:G94),3) -> 0.095 | O5: =ROUND(AVERAGE(H2:H94),3) -> 0.977 | P5: =ROUND(AVERAGE(I2:I94),3) -> 0.171
A6: Where can I take notes? | B6: Cognizance,Exposition | C6: desk,table,computer,mobile phone | D6: Cognizance,Exposition,Sensory,Acquisition,Achievement,Order,Construction,Exhibition,Retention,Conservance,Play,Injury avoidance,Breathing,Nurturance,Sleep,Toxicity avoidance,Laziness,Emission,Nursing,Thirst | E6: folder,computer,desk,notebook,bookshelf | F6: living room,kitchen | G6: 0.1 | H6: 1 | I6: =IF(G6+H6=0,0,2*G6*H6/(G6+H6)) -> 0.18181818 | J6: 0.4 | K6: 0.5 | L6: 340 | M6: =IF(J6+K6=0,0,ROUND(2*J6*K6/(J6+K6),3)) -> 0.444 | O6: 平均トークン
A7: Where can I brush my teeth? | B7: Conservance,Toxicity avoidance | C7: toothbrush,toothpaste,faucet,sink,toilet | D7: Toxicity avoidance,Conservance,Nursing,Nurturance,Emission,Sleep,Retention,Exhibition,Breathing,Sensory,Injury avoidance,Thirst,Exposition,Order,Hunger,Sexual,Achievement,Construction,Play,Acquisition | E7: bathroom counter,sink,toilet,toothpaste,toothbrush | F7: bathroom,kitchen | G7: 0.1 | H7: 1 | I7: =IF(G7+H7=0,0,2*G7*H7/(G7+H7)) -> 0.18181818 | J7: 0.8 | K7: 0.8 | L7: 398 | M7: =IF(J7+K7=0,0,ROUND(2*J7*K7/(J7+K7),3)) -> 0.8 | O7: =AVERAGE(L2:L94) -> 384.10753
A8: Where can I set if I want to warmup? | B8: Temperature | C8: stove,bed | D8: Temperature,Play,Laziness,Injury avoidance,Thirst,Sleep,Achievement,Hunger,Conservance,Exhibition,Nursing,Order,Sensory,Emission,Exposition,Breathing,Acquisition,Nurturance,Cognizance,Toxicity avoidance | E8: oven tray,stove | F8: kitchen | G8: 0.05 | H8: 1 | I8: =IF(G8+H8=0,0,2*G8*H8/(G8+H8)) -> 0.095238095 | J8: 0.5 | K8: 0.5 | L8: 392 | M8: =IF(J8+K8=0,0,ROUND(2*J8*K8/(J8+K8),3)) -> 0.5 | O8: 標準偏差
A9: Where can I check my appearance? | B9: Order,Exhibition,Exposition | C9: mirror | D9: Exhibition,Construction,Order,Sexual,Sensory,Exposition,Cognizance,Breathing,Conservance,Injury avoidance,Achievement,Emission,Temperature,Sleep,Hunger,Acquisition,Thirst,Retention,Nurturance,Nursing | E9: bathroom counter,hanger,mirror,face cream,soap | F9: living room,bedroom,bathroom,kitchen | G9: 0.15 | H9: 1 | I9: =IF(G9+H9=0,0,2*G9*H9/(G9+H9)) -> 0.26086957 | J9: 0.2 | K9: 1 | L9: 392 | M9: =IF(J9+K9=0,0,ROUND(2*J9*K9/(J9+K9),3)) -> 0.333 | O9: =_xlfn.STDEV.P(L2:L94) -> 24.129785
A10: Where should I put my jackets? | B10: Order,Conservance | C10: closet,hanger | D10: Exhibition,Temperature,Order,Retention,Sexual,Exposition,Injury avoidance,Nursing,Sleep,Hunger,Conservance,Construction,Acquisition,Emission,Thirst,Sensory,Laziness,Play,Nurturance,Achievement | E10: hanger,closet | F10: living room,bedroom,bathroom | G10: 0.1 | H10: 1 | I10: =IF(G10+H10=0,0,2*G10*H10/(G10+H10)) -> 0.18181818 | J10: 1 | K10: 1 | L10: 392 | M10: =IF(J10+K10=0,0,ROUND(2*J10*K10/(J10+K10),3)) -> 1
A11: Where can my kids go to read? | B11: Play,Cognizance | C11: book,chair,table,bed,sofa,desk | D11: Cognizance,Play,Nursing,Exposition,Laziness,Order,Acquisition,Achievement,Nurturance,Conservance,Toxicity avoidance,Sleep | E11: bookshelf,books,desk | F11: living room,bedroom,kitchen | G11: 0.167 | H11: 1 | I11: =IF(G11+H11=0,0,2*G11*H11/(G11+H11)) -> 0.28620394 | J11: 0.333 | K11: 0.167 | L11: 300 | M11: =IF(J11+K11=0,0,ROUND(2*J11*K11/(J11+K11),3)) -> 0.222
A12: Where can I put my jacket? | B12: Order,Conservance | C12: closet,hanger | D12: Exhibition,Temperature,Order,Retention,Sexual,Exposition,Injury avoidance,Nursing,Sleep,Hunger,Conservance,Construction,Acquisition,Emission,Thirst,Sensory,Laziness,Play,Nurturance,Achievement | E12: hanger,closet,sofa,towel rack | F12: living room,bedroom,bathroom,kitchen | G12: 0.1 | H12: 1 | I12: =IF(G12+H12=0,0,2*G12*H12/(G12+H12)) -> 0.18181818 | J12: 0.5 | K12: 1 | L12: 398 | M12: =IF(J12+K12=0,0,ROUND(2*J12*K12/(J12+K12),3)) -> 0.667
A13: Where can I wipe my shoes? | B13: Conservance,Order | C13: cleaning sponge,rug | D13: Emission,Injury avoidance,Conservance,Exhibition,Order,Toxicity avoidance,Nurturance,Retention,Sensory,Achievement,Sexual,Exposition,Construction,Thirst,Nursing,Acquisition,Sleep,Laziness,Breathing,Play | E13: rug,door | F13: living room,bedroom,bathroom,kitchen | G13: 0.1 | H13: 1 | I13: =IF(G13+H13=0,0,2*G13*H13/(G13+H13)) -> 0.18181818 | J13: 0.5 | K13: 0.5 | L13: 335 | M13: =IF(J13+K13=0,0,ROUND(2*J13*K13/(J13+K13),3)) -> 0.5
A14: Where can I put my hat? | B14: Order | C14: closet,closet drawers,hanger,desk,table | D14: Exhibition,Construction,Exposition,Temperature,Sleep,Order,Hunger,Laziness,Play,Achievement,Thirst,Nursing,Sexual,Retention,Acquisition,Injury avoidance,Emission,Conservance,Sensory,Nurturance | E14: hanger,sofa,kitchen table,nightstand,chair,closet,desk | F14: living room,bedroom,bathroom,kitchen | G14: 0.05 | H14: 1 | I14: =IF(G14+H14=0,0,2*G14*H14/(G14+H14)) -> 0.095238095 | J14: 0.429 | K14: 0.6 | L14: 405 | M14: =IF(J14+K14=0,0,ROUND(2*J14*K14/(J14+K14),3)) -> 0.5
A15: I want to take a nap. | B15: Sleep,Laziness | C15: bed,chair,sofa,private room,floor | D15: Sleep,Laziness,Play,Nursing,Thirst,Nurturance,Sensory,Hunger,Injury avoidance,Temperature,Achievement,Breathing,Conservance,Emission,Exhibition,Cognizance,Sexual,Order,Exposition,Retention | E15: bed,sofa,pillow,private room | F15: living room,bedroom,bathroom,kitchen | G15: 0.1 | H15: 1 | I15: =IF(G15+H15=0,0,2*G15*H15/(G15+H15)) -> 0.18181818 | J15: 0.75 | K15: 0.6 | L15: 397 | M15: =IF(J15+K15=0,0,ROUND(2*J15*K15/(J15+K15),3)) -> 0.667
A16: Where can I sit and eat if I don't want to use the dining table? | B16: Hunger | C16: desk,chair,sofa,private room, kitchen counter, kitchen table | D16: Exposition,Play,Hunger,Cognizance,Achievement,Order,Acquisition,Nursing,Laziness,Sleep,Toxicity avoidance,Conservance,Thirst,Construction,Exhibition,Retention,Sexual,Nurturance,Emission,Temperature | E16: sofa,bed,private room,chair,nightstand | F16: living room,bedroom,bathroom,kitchen | G16: 0.05 | H16: 1 | I16: =IF(G16+H16=0,0,2*G16*H16/(G16+H16)) -> 0.095238095 | J16: 0.6 | K16: 0.5 | L16: 403 | M16: =IF(J16+K16=0,0,ROUND(2*J16*K16/(J16+K16),3)) -> 0.545
A17: Where can I put my apples? | B17: Conservance,Order | C17: wall shelf,kitchen cabinet,kitchen counter,table,desk,kitchen table,dish | D17: Exposition,Hunger,Construction,Acquisition,Order,Sexual,Retention,Exhibition,Play,Laziness,Sleep,Achievement,Sensory,Thirst,Nursing,Conservance,Cognizance,Temperature,Emission,Injury avoidance | E17: bowl of dishes,refrigerator,kitchen table,kitchen cabinet,desk | F17: living room,kitchen | G17: 0.1 | H17: 1 | I17: =IF(G17+H17=0,0,2*G17*H17/(G17+H17)) -> 0.18181818 | J17: 0.6 | K17: 0.429 | L17: 398 | M17: =IF(J17+K17=0,0,ROUND(2*J17*K17/(J17+K17),3)) -> 0.5
